<?xml version="1.0"?>

<robot xmlns:xacro="http://www.ros.org/wiki/xacro" >
    
    <joint name="long_arm1_joint_x" type="revolute">
        <parent link="short_arm1_link"/>
        <child link="long_arm1_link"/>
        <origin xyz="0 ${short_arm_length} 0" rpy="0 0 0"/>
        <axis xyz="1 0 0"/>
        <limit lower="-3" upper="3" effort="100" velocity="100"/>
    </joint>

    <link name="long_arm1_link">
        <visual>
            <geometry>
                <sphere radius="0.006"/>
            </geometry>
            <origin xyz="0 0 0"/>
        </visual>
    </link>

    <joint name="long_arm1_joint_z" type="revolute">
        <parent link="long_arm1_link"/>
        <child link="long_arm1_link2"/>
        <origin xyz="0 0 0" rpy="0 0 0"/>
        <axis xyz="0 0 1"/>
        <limit lower="-3" upper="3" effort="100" velocity="100"/>
    </joint>

    <link name="long_arm1_link2">
        <visual>
            <geometry>
                <cylinder length = "${long_arm_length}" radius = "0.003"/>
            </geometry>
            <origin xyz="0 ${long_arm_length / 2 } 0" rpy="1.5708 0 0"/>
        </visual>
    </link>

    <joint name="long_arm2_joint_x" type="revolute">
        <parent link="short_arm2_link"/>
        <child link="long_arm2_link"/>
        <origin xyz="0 ${short_arm_length} 0" rpy="0 0 0"/>
        <axis xyz="1 0 0"/>
        <limit lower="-3" upper="3" effort="100" velocity="100"/>
    </joint>

    <link name="long_arm2_link">
        <visual>
            <geometry>
                <sphere radius="0.006"/>
            </geometry>
            <origin xyz="0 0 0"/>
        </visual>
    </link>

    <joint name="long_arm2_joint_z" type="revolute">
        <parent link="long_arm2_link"/>
        <child link="long_arm2_link2"/>
        <origin xyz="0 0 0" rpy="0 0 0"/>
        <axis xyz="0 0 1"/>
        <limit lower="-3" upper="3" effort="100" velocity="100"/>
    </joint>

    <link name="long_arm2_link2">
        <visual>
            <geometry>
                <cylinder length = "${long_arm_length}" radius = "0.003"/>
            </geometry>
            <origin xyz="0 ${long_arm_length / 2 } 0" rpy="1.5708 0 0"/>
        </visual>
    </link>

    <joint name="long_arm3_joint_x" type="revolute">
        <parent link="short_arm3_link"/>
        <child link="long_arm3_link"/>
        <origin xyz="0 ${short_arm_length} 0" rpy="0 0 0"/>
        <axis xyz="1 0 0"/>
        <limit lower="-3" upper="3" effort="100" velocity="100"/>
    </joint>

    <link name="long_arm3_link">
        <visual>
            <geometry>
                <sphere radius="0.006"/>
            </geometry>
            <origin xyz="0 0 0"/>
        </visual>
    </link>

    <joint name="long_arm3_joint_z" type="revolute">
        <parent link="long_arm3_link"/>
        <child link="long_arm3_link2"/>
        <origin xyz="0 0 0" rpy="0 0 0"/>
        <axis xyz="0 0 1"/>
        <limit lower="-3" upper="3" effort="100" velocity="100"/>
    </joint>

    <link name="long_arm3_link2">
        <visual>
            <geometry>
                <cylinder length = "${long_arm_length}" radius = "0.003"/>
            </geometry>
            <origin xyz="0 ${long_arm_length / 2 } 0" rpy="1.5708 0 0"/>
        </visual>
    </link>

    <joint name="long_arm4_joint_x" type="revolute">
        <parent link="short_arm4_link"/>
        <child link="long_arm4_link"/>
        <origin xyz="0 ${short_arm_length} 0" rpy="0 0 0"/>
        <axis xyz="1 0 0"/>
        <limit lower="-3" upper="3" effort="100" velocity="100"/>
    </joint>

    <link name="long_arm4_link">
        <visual>
            <geometry>
                <sphere radius="0.006"/>
            </geometry>
            <origin xyz="0 0 0"/>
        </visual>
    </link>

    <joint name="long_arm4_joint_z" type="revolute">
        <parent link="long_arm4_link"/>
        <child link="long_arm4_link2"/>
        <origin xyz="0 0 0" rpy="0 0 0"/>
        <axis xyz="0 0 1"/>
        <limit lower="-3" upper="3" effort="100" velocity="100"/>
    </joint>

    <link name="long_arm4_link2">
        <visual>
            <geometry>
                <cylinder length = "${long_arm_length}" radius = "0.003"/>
            </geometry>
            <origin xyz="0 ${long_arm_length / 2 } 0" rpy="1.5708 0 0"/>
        </visual>
    </link>

    <joint name="long_arm5_joint_x" type="revolute">
        <parent link="short_arm5_link"/>
        <child link="long_arm5_link"/>
        <origin xyz="0 ${short_arm_length} 0" rpy="0 0 0"/>
        <axis xyz="1 0 0"/>
        <limit lower="-3" upper="3" effort="100" velocity="100"/>
    </joint>

    <link name="long_arm5_link">
        <visual>
            <geometry>
                <sphere radius="0.006"/>
            </geometry>
            <origin xyz="0 0 0"/>
        </visual>
    </link>

    <joint name="long_arm5_joint_z" type="revolute">
        <parent link="long_arm5_link"/>
        <child link="long_arm5_link2"/>
        <origin xyz="0 0 0" rpy="0 0 0"/>
        <axis xyz="0 0 1"/>
        <limit lower="-3" upper="3" effort="100" velocity="100"/>
    </joint>

    <link name="long_arm5_link2">
        <visual>
            <geometry>
                <cylinder length = "${long_arm_length}" radius = "0.003"/>
            </geometry>
            <origin xyz="0 ${long_arm_length / 2 } 0" rpy="1.5708 0 0"/>
        </visual>
    </link>

    <joint name="long_arm6_joint_x" type="revolute">
        <parent link="short_arm6_link"/>
        <child link="long_arm6_link"/>
        <origin xyz="0 ${short_arm_length} 0" rpy="0 0 0"/>
        <axis xyz="1 0 0"/>
        <limit lower="-3" upper="3" effort="100" velocity="100"/>
    </joint>

    <link name="long_arm6_link">
        <visual>
            <geometry>
                <sphere radius="0.006"/>
            </geometry>
            <origin xyz="0 0 0"/>
        </visual>
    </link>

    <joint name="long_arm6_joint_z" type="revolute">
        <parent link="long_arm6_link"/>
        <child link="long_arm6_link2"/>
        <origin xyz="0 0 0" rpy="0 0 0"/>
        <axis xyz="0 0 1"/>
        <limit lower="-3" upper="3" effort="100" velocity="100"/>
    </joint>

    <link name="long_arm6_link2">
        <visual>
            <geometry>
                <cylinder length = "${long_arm_length}" radius = "0.003"/>
            </geometry>
            <origin xyz="0 ${long_arm_length / 2 } 0" rpy="1.5708 0 0"/>
        </visual>
    </link>

    
</robot>