<?xml version="1.0"?>

<robot xmlns:xacro="http://www.ros.org/wiki/xacro" >


    <xacro:property name="short_arm_length" value="0.050"/>
    <xacro:property name="long_arm_length" value="0.133"/>


    <joint name="short_arm1_joint" type="revolute">
        <parent link="servo1_link"/>
        <child link="short_arm1_link"/>
        <origin xyz="0 0 0" rpy="0 0 0"/>
        <axis xyz="1 0 0"/>
        <limit lower="-1.5708" upper="1.5708" effort="100" velocity="100"/>
    </joint>

    <link name="short_arm1_link">
        <visual>
            <geometry>
                <cylinder length = "${short_arm_length}" radius = "0.005"/>
            </geometry>
            <origin xyz="0 ${short_arm_length / 2 } 0" rpy="1.5708 0 0"/>
        </visual>
    </link>

    <joint name="short_arm2_joint" type="revolute">
        <parent link="servo2_link"/>
        <child link="short_arm2_link"/>
        <origin xyz="0 0 0" rpy="0 0 0"/>
        <axis xyz="1 0 0"/>
        <limit lower="-1.5708" upper="1.5708" effort="100" velocity="100"/>
    </joint>

    <link name="short_arm2_link">
        <visual>
            <geometry>
                <cylinder length = "${short_arm_length}" radius = "0.005"/>
            </geometry>
            <origin xyz="0 ${short_arm_length / 2 } 0" rpy="1.5708 0 0"/>
        </visual>   
    </link>

    <joint name="short_arm3_joint" type="revolute">
        <parent link="servo3_link"/>
        <child link="short_arm3_link"/>
        <origin xyz="0 0 0" rpy="0 0 0"/>
        <axis xyz="1 0 0"/>
        <limit lower="-1.5708" upper="1.5708" effort="100" velocity="100"/>
    </joint>

    <link name="short_arm3_link">
        <visual>
            <geometry>
                <cylinder length = "${short_arm_length}" radius = "0.005"/>
            </geometry>
            <origin xyz="0 ${short_arm_length / 2 } 0" rpy="1.5708 0 0"/>
        </visual>
    </link>

    <joint name="short_arm4_joint" type="revolute">
        <parent link="servo4_link"/>
        <child link="short_arm4_link"/>
        <origin xyz="0 0 0" rpy="0 0 0"/>
        <axis xyz="1 0 0"/>
        <limit lower="-1.5708" upper="1.5708" effort="100" velocity="100"/>
    </joint>
    
    <link name="short_arm4_link">
        <visual>
            <geometry>
                <cylinder length = "${short_arm_length}" radius = "0.005"/>
            </geometry>
            <origin xyz="0 ${short_arm_length / 2 } 0" rpy="1.5708 0 0"/>
        </visual>
    </link>

    <joint name="short_arm5_joint" type="revolute">
        <parent link="servo5_link"/>
        <child link="short_arm5_link"/>
        <origin xyz="0 0 0" rpy="0 0 0"/>
        <axis xyz="1 0 0"/>
        <limit lower="-1.5708" upper="1.5708" effort="100" velocity="100"/>
    </joint>

    <link name="short_arm5_link">
        <visual>
            <geometry>
                <cylinder length = "${short_arm_length}" radius = "0.005"/>
            </geometry>
            <origin xyz="0 ${short_arm_length / 2 } 0" rpy="1.5708 0 0"/>
        </visual>
    </link>

    <joint name="short_arm6_joint" type="revolute">
        <parent link="servo6_link"/>
        <child link="short_arm6_link"/>
        <origin xyz="0 0 0" rpy="0 0 0"/>
        <axis xyz="1 0 0"/>
        <limit lower="-1.5708" upper="1.5708" effort="100" velocity="100"/>
    </joint>

    <link name="short_arm6_link">
        <visual>
            <geometry>
                <cylinder length = "${short_arm_length}" radius = "0.005"/>
            </geometry>
            <origin xyz="0 ${short_arm_length / 2 } 0" rpy="1.5708 0 0"/>
        </visual>
    </link>
</robot>