<?xml version="1.0" ?>
<!-- =================================================================================== -->
<!-- |    This document was autogenerated by xacro from robot.urdf.xacro               | -->
<!-- |    EDITING THIS FILE BY HAND IS NOT RECOMMENDED                                 | -->
<!-- =================================================================================== -->
<robot name="robot">
  <!--model of the base of the robot without collision on the main geometries. Spheres are used to set collisions-->
  <material name="white">
    <color rgba="0.95 0.95 0.95 1"/>
  </material>
  <material name="black">
    <color rgba="0.2 0.2 0.2 1"/>
  </material>
  <!--Base  of the robot -->
  <link name="base_link">
    <visual>
      <material name="white"/>
      <geometry>
        <cylinder length="0.035" radius="0.06"/>
        <!-- <mesh filename="package://robot/urdf/simplified_base_model.stl"/> -->
      </geometry>
      <origin rpy="0 0 -0.523" xyz="0 0 0.02"/>
    </visual>
    <inertial>
      <origin rpy="0 0 0" xyz="0 0 1"/>
      <mass value="0.15"/>
      <inertia ixx="0.00024" ixy="0.0" ixz="0.0" iyy="0.00025" iyz="0.0" izz="0.00041"/>
    </inertial>
  </link>
  <!--servo link macro-->
  <!--macro for collision spheres-->
  <!--add collision spheres to base-->
  <joint name="collision_joint1" type="fixed">
    <parent link="base_link"/>
    <child link="collision_link1"/>
    <origin xyz="-0.06 0.0 0.02"/>
  </joint>
  <link name="collision_link1">
    <visual>
      <material name="white"/>
      <geometry>
        <sphere radius="0.02"/>
      </geometry>
    </visual>
    <collision>
      <geometry>
        <sphere radius="0.02"/>
      </geometry>
    </collision>
    <inertial>
      <origin xyz="0.0 0.0 0.0"/>
      <mass value="0.06"/>
      <inertia ixx="0.000015" ixy="0.0" ixz="0.0" iyy="0.000015" iyz="0.0" izz="0.000015"/>
    </inertial>
  </link>
  <joint name="collision_joint2" type="fixed">
    <parent link="base_link"/>
    <child link="collision_link2"/>
    <origin xyz="0.03 -0.0519 0.02"/>
  </joint>
  <link name="collision_link2">
    <visual>
      <material name="white"/>
      <geometry>
        <sphere radius="0.02"/>
      </geometry>
    </visual>
    <collision>
      <geometry>
        <sphere radius="0.02"/>
      </geometry>
    </collision>
    <inertial>
      <origin xyz="0.0 0.0 0.0"/>
      <mass value="0.06"/>
      <inertia ixx="0.000015" ixy="0.0" ixz="0.0" iyy="0.000015" iyz="0.0" izz="0.000015"/>
    </inertial>
  </link>
  <joint name="collision_joint3" type="fixed">
    <parent link="base_link"/>
    <child link="collision_link3"/>
    <origin xyz="0.03 0.0519 0.02"/>
  </joint>
  <link name="collision_link3">
    <visual>
      <material name="white"/>
      <geometry>
        <sphere radius="0.02"/>
      </geometry>
    </visual>
    <collision>
      <geometry>
        <sphere radius="0.02"/>
      </geometry>
    </collision>
    <inertial>
      <origin xyz="0.0 0.0 0.0"/>
      <mass value="0.06"/>
      <inertia ixx="0.000015" ixy="0.0" ixz="0.0" iyy="0.000015" iyz="0.0" izz="0.000015"/>
    </inertial>
  </link>
  <!--add joints and links for the servos -->
  <joint name="servo1_joint" type="fixed">
    <parent link="base_link"/>
    <child link="servo1_link"/>
    <origin rpy="0 -0.349066 2.0944" xyz="-0.07159 0.05282 0.043"/>
  </joint>
  <link name="servo1_link">
    <visual>
      <material name="black"/>
      <geometry>
        <box size="0.030 0.040 0.020"/>
      </geometry>
      <origin xyz="-0.023 -0.010 0"/>
    </visual>
    <inertial>
      <origin xyz="-0.023 -0.010 0"/>
      <mass value="0.060"/>
      <inertia ixx="0.00001" ixy="0.0" ixz="0.0" iyy="0.0000065" iyz="0.0" izz="0.0000125"/>
    </inertial>
  </link>
  <joint name="servo2_joint" type="fixed">
    <parent link="base_link"/>
    <child link="servo2_link"/>
    <origin rpy="3.14159 -0.349066 2.0944" xyz="-0.00967 0.08825 0.043"/>
  </joint>
  <link name="servo2_link">
    <visual>
      <material name="black"/>
      <geometry>
        <box size="0.030 0.040 0.020"/>
      </geometry>
      <origin xyz="-0.023 -0.010 0"/>
    </visual>
    <inertial>
      <origin xyz="-0.023 -0.010 0"/>
      <mass value="0.060"/>
      <inertia ixx="0.00001" ixy="0.0" ixz="0.0" iyy="0.0000065" iyz="0.0" izz="0.0000125"/>
    </inertial>
  </link>
  <joint name="servo3_joint" type="fixed">
    <parent link="base_link"/>
    <child link="servo3_link"/>
    <origin rpy="0 -0.349066 0" xyz="0.08126 0.03575 0.043"/>
  </joint>
  <link name="servo3_link">
    <visual>
      <material name="black"/>
      <geometry>
        <box size="0.030 0.040 0.020"/>
      </geometry>
      <origin xyz="-0.023 -0.010 0"/>
    </visual>
    <inertial>
      <origin xyz="-0.023 -0.010 0"/>
      <mass value="0.060"/>
      <inertia ixx="0.00001" ixy="0.0" ixz="0.0" iyy="0.0000065" iyz="0.0" izz="0.0000125"/>
    </inertial>
  </link>
  <joint name="servo4_joint" type="fixed">
    <parent link="base_link"/>
    <child link="servo4_link"/>
    <origin rpy="3.14159 -0.349066 0" xyz="0.08126 -0.03567 0.043"/>
  </joint>
  <link name="servo4_link">
    <visual>
      <material name="black"/>
      <geometry>
        <box size="0.030 0.040 0.020"/>
      </geometry>
      <origin xyz="-0.023 -0.010 0"/>
    </visual>
    <inertial>
      <origin xyz="-0.023 -0.010 0"/>
      <mass value="0.060"/>
      <inertia ixx="0.00001" ixy="0.0" ixz="0.0" iyy="0.0000065" iyz="0.0" izz="0.0000125"/>
    </inertial>
  </link>
  <joint name="servo5_joint" type="fixed">
    <parent link="base_link"/>
    <child link="servo5_link"/>
    <origin rpy="0 -0.349066 4.18879" xyz="-0.00967 -0.08825 0.043"/>
  </joint>
  <link name="servo5_link">
    <visual>
      <material name="black"/>
      <geometry>
        <box size="0.030 0.040 0.020"/>
      </geometry>
      <origin xyz="-0.023 -0.010 0"/>
    </visual>
    <inertial>
      <origin xyz="-0.023 -0.010 0"/>
      <mass value="0.060"/>
      <inertia ixx="0.00001" ixy="0.0" ixz="0.0" iyy="0.0000065" iyz="0.0" izz="0.0000125"/>
    </inertial>
  </link>
  <joint name="servo6_joint" type="fixed">
    <parent link="base_link"/>
    <child link="servo6_link"/>
    <origin rpy="3.14159 -0.349066 4.18879" xyz="-0.07159 -0.0525 0.043"/>
  </joint>
  <link name="servo6_link">
    <visual>
      <material name="black"/>
      <geometry>
        <box size="0.030 0.040 0.020"/>
      </geometry>
      <origin xyz="-0.023 -0.010 0"/>
    </visual>
    <inertial>
      <origin xyz="-0.023 -0.010 0"/>
      <mass value="0.060"/>
      <inertia ixx="0.00001" ixy="0.0" ixz="0.0" iyy="0.0000065" iyz="0.0" izz="0.0000125"/>
    </inertial>
  </link>
  <!--macro for setting up arm link and joint-->
  <!--call short_arm macro to create all 6 arms-->
  <joint name="short_arm1_joint" type="revolute">
    <parent link="servo1_link"/>
    <child link="short_arm1_link"/>
    <origin rpy="0 0 0" xyz="0 0 0"/>
    <axis xyz="1 0 0"/>
    <limit effort=".12" lower="-1.5708" upper="1.5708" velocity="5"/>
    <dynamics damping="1.0" friction="0.2"/>
  </joint>
  <link name="short_arm1_link">
    <visual>
      <material name="white"/>
      <geometry>
        <cylinder length="0.075" radius="0.005"/>
      </geometry>
      <origin rpy="1.5708 0 0" xyz="0 0.0375 0"/>
    </visual>
    <inertial>
      <origin rpy="1.5708 0 0" xyz="0 0.0375 0"/>
      <mass value="0.060"/>
      <inertia ixx="0.00001" ixy="0.0" ixz="0.0" iyy="0.0000065" iyz="0.0" izz="0.0000125"/>
    </inertial>
  </link>
  <joint name="end_short_arm1_joint" type="fixed">
    <parent link="short_arm1_link"/>
    <child link="end_short_arm1_link"/>
    <origin xyz="0 0.075 0"/>
  </joint>
  <link name="end_short_arm1_link">
    <visual>
      <material name="white"/>
      <geometry>
        <sphere radius="0.0075"/>
      </geometry>
    </visual>
    <collision>
      <geometry>
        <sphere radius="0.0075"/>
      </geometry>
    </collision>
    <inertial>
      <origin xyz="0.0 0.0 0.0"/>
      <mass value="0.01"/>
      <inertia ixx="0.000002" ixy="0.0" ixz="0.0" iyy="0.000002" iyz="0.0" izz="0.000002"/>
    </inertial>
  </link>
  <joint name="short_arm2_joint" type="revolute">
    <parent link="servo2_link"/>
    <child link="short_arm2_link"/>
    <origin rpy="0 0 0" xyz="0 0 0"/>
    <axis xyz="1 0 0"/>
    <limit effort=".12" lower="-1.5708" upper="1.5708" velocity="5"/>
    <dynamics damping="1.0" friction="0.2"/>
  </joint>
  <link name="short_arm2_link">
    <visual>
      <material name="white"/>
      <geometry>
        <cylinder length="0.075" radius="0.005"/>
      </geometry>
      <origin rpy="1.5708 0 0" xyz="0 0.0375 0"/>
    </visual>
    <inertial>
      <origin rpy="1.5708 0 0" xyz="0 0.0375 0"/>
      <mass value="0.060"/>
      <inertia ixx="0.00001" ixy="0.0" ixz="0.0" iyy="0.0000065" iyz="0.0" izz="0.0000125"/>
    </inertial>
  </link>
  <joint name="end_short_arm2_joint" type="fixed">
    <parent link="short_arm2_link"/>
    <child link="end_short_arm2_link"/>
    <origin xyz="0 0.075 0"/>
  </joint>
  <link name="end_short_arm2_link">
    <visual>
      <material name="white"/>
      <geometry>
        <sphere radius="0.0075"/>
      </geometry>
    </visual>
    <collision>
      <geometry>
        <sphere radius="0.0075"/>
      </geometry>
    </collision>
    <inertial>
      <origin xyz="0.0 0.0 0.0"/>
      <mass value="0.01"/>
      <inertia ixx="0.000002" ixy="0.0" ixz="0.0" iyy="0.000002" iyz="0.0" izz="0.000002"/>
    </inertial>
  </link>
  <joint name="short_arm3_joint" type="revolute">
    <parent link="servo3_link"/>
    <child link="short_arm3_link"/>
    <origin rpy="0 0 0" xyz="0 0 0"/>
    <axis xyz="1 0 0"/>
    <limit effort=".12" lower="-1.5708" upper="1.5708" velocity="5"/>
    <dynamics damping="1.0" friction="0.2"/>
  </joint>
  <link name="short_arm3_link">
    <visual>
      <material name="white"/>
      <geometry>
        <cylinder length="0.075" radius="0.005"/>
      </geometry>
      <origin rpy="1.5708 0 0" xyz="0 0.0375 0"/>
    </visual>
    <inertial>
      <origin rpy="1.5708 0 0" xyz="0 0.0375 0"/>
      <mass value="0.060"/>
      <inertia ixx="0.00001" ixy="0.0" ixz="0.0" iyy="0.0000065" iyz="0.0" izz="0.0000125"/>
    </inertial>
  </link>
  <joint name="end_short_arm3_joint" type="fixed">
    <parent link="short_arm3_link"/>
    <child link="end_short_arm3_link"/>
    <origin xyz="0 0.075 0"/>
  </joint>
  <link name="end_short_arm3_link">
    <visual>
      <material name="white"/>
      <geometry>
        <sphere radius="0.0075"/>
      </geometry>
    </visual>
    <collision>
      <geometry>
        <sphere radius="0.0075"/>
      </geometry>
    </collision>
    <inertial>
      <origin xyz="0.0 0.0 0.0"/>
      <mass value="0.01"/>
      <inertia ixx="0.000002" ixy="0.0" ixz="0.0" iyy="0.000002" iyz="0.0" izz="0.000002"/>
    </inertial>
  </link>
  <joint name="short_arm4_joint" type="revolute">
    <parent link="servo4_link"/>
    <child link="short_arm4_link"/>
    <origin rpy="0 0 0" xyz="0 0 0"/>
    <axis xyz="1 0 0"/>
    <limit effort=".12" lower="-1.5708" upper="1.5708" velocity="5"/>
    <dynamics damping="1.0" friction="0.2"/>
  </joint>
  <link name="short_arm4_link">
    <visual>
      <material name="white"/>
      <geometry>
        <cylinder length="0.075" radius="0.005"/>
      </geometry>
      <origin rpy="1.5708 0 0" xyz="0 0.0375 0"/>
    </visual>
    <inertial>
      <origin rpy="1.5708 0 0" xyz="0 0.0375 0"/>
      <mass value="0.060"/>
      <inertia ixx="0.00001" ixy="0.0" ixz="0.0" iyy="0.0000065" iyz="0.0" izz="0.0000125"/>
    </inertial>
  </link>
  <joint name="end_short_arm4_joint" type="fixed">
    <parent link="short_arm4_link"/>
    <child link="end_short_arm4_link"/>
    <origin xyz="0 0.075 0"/>
  </joint>
  <link name="end_short_arm4_link">
    <visual>
      <material name="white"/>
      <geometry>
        <sphere radius="0.0075"/>
      </geometry>
    </visual>
    <collision>
      <geometry>
        <sphere radius="0.0075"/>
      </geometry>
    </collision>
    <inertial>
      <origin xyz="0.0 0.0 0.0"/>
      <mass value="0.01"/>
      <inertia ixx="0.000002" ixy="0.0" ixz="0.0" iyy="0.000002" iyz="0.0" izz="0.000002"/>
    </inertial>
  </link>
  <joint name="short_arm5_joint" type="revolute">
    <parent link="servo5_link"/>
    <child link="short_arm5_link"/>
    <origin rpy="0 0 0" xyz="0 0 0"/>
    <axis xyz="1 0 0"/>
    <limit effort=".12" lower="-1.5708" upper="1.5708" velocity="5"/>
    <dynamics damping="1.0" friction="0.2"/>
  </joint>
  <link name="short_arm5_link">
    <visual>
      <material name="white"/>
      <geometry>
        <cylinder length="0.075" radius="0.005"/>
      </geometry>
      <origin rpy="1.5708 0 0" xyz="0 0.0375 0"/>
    </visual>
    <inertial>
      <origin rpy="1.5708 0 0" xyz="0 0.0375 0"/>
      <mass value="0.060"/>
      <inertia ixx="0.00001" ixy="0.0" ixz="0.0" iyy="0.0000065" iyz="0.0" izz="0.0000125"/>
    </inertial>
  </link>
  <joint name="end_short_arm5_joint" type="fixed">
    <parent link="short_arm5_link"/>
    <child link="end_short_arm5_link"/>
    <origin xyz="0 0.075 0"/>
  </joint>
  <link name="end_short_arm5_link">
    <visual>
      <material name="white"/>
      <geometry>
        <sphere radius="0.0075"/>
      </geometry>
    </visual>
    <collision>
      <geometry>
        <sphere radius="0.0075"/>
      </geometry>
    </collision>
    <inertial>
      <origin xyz="0.0 0.0 0.0"/>
      <mass value="0.01"/>
      <inertia ixx="0.000002" ixy="0.0" ixz="0.0" iyy="0.000002" iyz="0.0" izz="0.000002"/>
    </inertial>
  </link>
  <joint name="short_arm6_joint" type="revolute">
    <parent link="servo6_link"/>
    <child link="short_arm6_link"/>
    <origin rpy="0 0 0" xyz="0 0 0"/>
    <axis xyz="1 0 0"/>
    <limit effort=".12" lower="-1.5708" upper="1.5708" velocity="5"/>
    <dynamics damping="1.0" friction="0.2"/>
  </joint>
  <link name="short_arm6_link">
    <visual>
      <material name="white"/>
      <geometry>
        <cylinder length="0.075" radius="0.005"/>
      </geometry>
      <origin rpy="1.5708 0 0" xyz="0 0.0375 0"/>
    </visual>
    <inertial>
      <origin rpy="1.5708 0 0" xyz="0 0.0375 0"/>
      <mass value="0.060"/>
      <inertia ixx="0.00001" ixy="0.0" ixz="0.0" iyy="0.0000065" iyz="0.0" izz="0.0000125"/>
    </inertial>
  </link>
  <joint name="end_short_arm6_joint" type="fixed">
    <parent link="short_arm6_link"/>
    <child link="end_short_arm6_link"/>
    <origin xyz="0 0.075 0"/>
  </joint>
  <link name="end_short_arm6_link">
    <visual>
      <material name="white"/>
      <geometry>
        <sphere radius="0.0075"/>
      </geometry>
    </visual>
    <collision>
      <geometry>
        <sphere radius="0.0075"/>
      </geometry>
    </collision>
    <inertial>
      <origin xyz="0.0 0.0 0.0"/>
      <mass value="0.01"/>
      <inertia ixx="0.000002" ixy="0.0" ixz="0.0" iyy="0.000002" iyz="0.0" izz="0.000002"/>
    </inertial>
  </link>
  <!-- This file demonstrates the use of some <gazebo> tags -->
  <!-- To include it add the following line -->
  <!-- <xacro:include filename="example_gazebo.xacro" /> -->
  <!-- Gazebo is unable to use the same <material> tags that are already in the URDF (that RViz uses). -->
  <!-- Instead, we need to add gazebo tags for our links that refer to Gazebo materials -->
  <gazebo reference="collision_link1">
    <mu1>0.2</mu1>
    <mu2>0.3</mu2>
  </gazebo>
  <gazebo reference="collision_link2">
    <mu1>0.2</mu1>
    <mu2>0.3</mu2>
  </gazebo>
  <gazebo reference="collision_link3">
    <mu1>0.2</mu1>
    <mu2>0.3</mu2>
  </gazebo>
  <gazebo reference="end_short_arm1_link">
    <mu1>0.2</mu1>
    <mu2>0.3</mu2>
  </gazebo>
  <gazebo reference="end_short_arm2_link">
    <mu1>0.2</mu1>
    <mu2>0.3</mu2>
  </gazebo>
  <gazebo reference="end_short_arm3_link">
    <mu1>0.2</mu1>
    <mu2>0.3</mu2>
  </gazebo>
  <gazebo reference="end_short_arm4_link">
    <mu1>0.2</mu1>
    <mu2>0.3</mu2>
  </gazebo>
  <gazebo reference="end_short_arm5_link">
    <mu1>0.2</mu1>
    <mu2>0.3</mu2>
  </gazebo>
  <gazebo reference="end_short_arm6_link">
    <mu1>0.2</mu1>
    <mu2>0.3</mu2>
  </gazebo>
  <gazebo reference="base_link">
    <material>Gazebo/Green</material>
  </gazebo>
  <gazebo reference="servo1_link">
    <material>Gazebo/Blue</material>
  </gazebo>
  <gazebo reference="servo2_link">
    <material>Gazebo/Blue</material>
  </gazebo>
  <gazebo reference="servo3_link">
    <material>Gazebo/Blue</material>
  </gazebo>
  <gazebo reference="servo4_link">
    <material>Gazebo/Blue</material>
  </gazebo>
  <gazebo reference="servo5_link">
    <material>Gazebo/Blue</material>
  </gazebo>
  <gazebo reference="servo6_link">
    <material>Gazebo/Blue</material>
  </gazebo>
  <gazebo reference="short_arm1_link">
    <material>Gazebo/Orange</material>
  </gazebo>
  <gazebo reference="short_arm2_link">
    <material>Gazebo/Orange</material>
  </gazebo>
  <gazebo reference="short_arm3_link">
    <material>Gazebo/Orange</material>
  </gazebo>
  <gazebo reference="short_arm4_link">
    <material>Gazebo/Orange</material>
  </gazebo>
  <gazebo reference="short_arm5_link">
    <material>Gazebo/Orange</material>
  </gazebo>
  <gazebo reference="short_arm6_link">
    <material>Gazebo/Orange</material>
  </gazebo>
  <!-- Gazebo requires the use of plugins to interact with other systems such as ROS. -->
  <!-- This plugin will publish the joint_states for the selected joints 
            (which robot_state_publisher can then use to broadcast the approprate tf). -->
  <gazebo>
    <plugin filename="libgazebo_ros_joint_state_publisher.so" name="gazebo_ros_joint_state_publisher">
      <update_rate>20</update_rate>
      <joint_name>short_arm1_joint</joint_name>
      <joint_name>short_arm2_joint</joint_name>
      <joint_name>short_arm3_joint</joint_name>
      <joint_name>short_arm4_joint</joint_name>
      <joint_name>short_arm5_joint</joint_name>
      <joint_name>short_arm6_joint</joint_name>
    </plugin>
  </gazebo>
  <!-- This plugin will read a JointTrajectory message from the /set_joint_trajectory topic 
            and move the machine accordingly. It's a bit clunky but it works. -->
  <!-- You'll probably want to add damping to the joints to stop them it flopping around. 
            e.g. <dynamics damping="10.0" friction="10.0"/> -->
  <!-- Here's an example message to publish to test it:
            ros2 topic pub -1 /set_joint_trajectory trajectory_msgs/msg/JointTrajectory  '{header: {frame_id: world}, joint_names: [slider_joint, arm_joint], points: [  {positions: {0.8,0.6}} ]}' -->
  <gazebo>
    <plugin filename="libgazebo_ros_joint_pose_trajectory.so" name="gazebo_ros_joint_pose_trajectory">
      <!--#<update_rate>20</update_rate>-->
    </plugin>
  </gazebo>
</robot>
